Workbook

Sheet README
A1: PriorityOne: source data
A2: One tab per source system, holding the exact rows the demo app was seeded with, shaped the way each system would deliver them.
A3: All accounts, people, figures and links are invented mock data.
A4: Data as of the week of 05 Oct 2026. Regenerate after seeding: python export_sources.py
A5: Blue text = an input you can change. Green text = a formula pulling from another tab. Hover a tab's A1 cell for notes.
A7: Tab | B7: Source System | C7: What It Holds | D7: Feeds These Signals | E7: Rows
A8: SF Accounts | B8: Salesforce | C8: Accounts: segment, ARR, owner, contacts, exec activity | D8: contact_departed, exec_sponsor_gap, single_threaded; importance | E8: =COUNTA('SF Accounts'!A:A)-1
A9: SF Contacts | B9: Salesforce | C9: People at each customer: role, email, last activity | D9: contact ranking, email drafts, suggested steps | E9: =COUNTA('SF Contacts'!A:A)-1
A10: SF Contracts | B10: Salesforce | C10: Contracts and their end (renewal) dates | D10: renewal_approaching | E10: =COUNTA('SF Contracts'!A:A)-1
A11: SF QBR Events | B11: Salesforce | C11: Latest QBR per account | D11: qbr_overdue, no_contact_90d | E11: =COUNTA('SF QBR Events'!A:A)-1
A12: Payments weekly | B12: Payments data warehouse | C12: Weekly volume, auth rate, chargebacks, failed payouts | D12: volume_drop, volume_growth, auth_rate_drop, chargeback_spike, failed_payout | E12: =COUNTA('Payments weekly'!A:A)-1
A13: Payment methods | B13: Payments data warehouse | C13: Methods enabled per merchant, with dates | D13: payment_method_gap | E13: =COUNTA('Payment methods'!A:A)-1
A14: Support tickets | B14: Support desk | C14: Sev-1 tickets | D14: sev1_open | E14: =COUNTA('Support tickets'!A:A)-1
A15: Support weekly | B15: Support desk | C15: Open ticket counts per week | D15: (context) | E15: =COUNTA('Support weekly'!A:A)-1
A16: Gong calls | B16: Gong | C16: Call briefs, attendees, extracted risks/opportunities, sentiment | D16: cross_sell_fit, sentiment_decline, no_contact_90d; contact call history | E16: =COUNTA('Gong calls'!A:A)-1
A17: Slack messages | B17: Slack (shared channels) | C17: Customer messages, classified | D17: contact_departed | E17: =COUNTA('Slack messages'!A:A)-1
A18: NPS responses | B18: NPS survey | C18: Relationship NPS by contact | D18: nps_detractor | E18: =COUNTA('NPS responses'!A:A)-1
A19: Sync log | B19: Ingestion log | C19: Every successful sync per source | D19: freshness → 'data incomplete' badges | E19: =COUNTA('Sync log'!A:A)-1
A20: Source freshness | B20: Computed here | C20: Newest sync and stale flag per source | D20: (formulas) | E20: –
A21: Signals (output) | B21: PriorityOne | C21: What the tracker detected, with history | D21: OUTPUT | E21: =COUNTA('Signals (output)'!A:A)-1
A22: Weekly lists (output) | B22: PriorityOne | C22: This week's scored and ranked accounts | D22: OUTPUT | E22: =COUNTA('Weekly lists (output)'!A:A)-1
A24: Connected tools that don't feed the tracker (Clay enrichment, Looker dashboards) have no tab. Gong is deliberately 12 days stale, which is why some accounts show 'data incomplete'.

Sheet SF Accounts
A1: Account Id | B1: Account Name | C1: Segment | D1: Vertical | E1: Region | F1: ARR (USD) | G1: Customer Since | H1: Account Owner | I1: CSM | J1: Primary Contact | K1: Previous Primary Contact | L1: Contact Changed On | M1: Exec Sponsor Last Contact | N1: Engaged Contacts (90d) | O1: Record URL
A2: 001604FPg2A94Rf | B2: Alder Bazaar | C2: SMB | D2: marketplace | E2: APAC | F2: 122000 | G2: 44352 | H2: Tom Whitaker | I2: David Nakamura | J2: Olivia Rossi | N2: 1 | O2: https://adyen.my.salesforce.com/001604FPg2A94Rf
A3: 0016kz7PLAp9Nh9 | B3: Alder Bites | C3: Mid-Market | D3: food delivery | E3: EMEA | F3: 479000 | G3: 45163 | H3: Lena Fischer | I3: Pedro Silva | J3: Aiko Jansen | N3: 4 | O3: https://adyen.my.salesforce.com/0016kz7PLAp9Nh9
A4: 0016sQhnhNjZAmX | B4: Alder Box | C4: Mid-Market | D4: subscription | E4: EMEA | F4: 640000 | G4: 45319 | H4: Lena Fischer | I4: Yusuf Jansen | J4: Aiko Petrov | N4: 3 | O4: https://adyen.my.salesforce.com/0016sQhnhNjZAmX
A5: 0016ZF3MwRjiDpu | B5: Alder Exchange | C5: Enterprise | D5: marketplace | E5: EMEA | F5: 6996000 | G5: 44404 | H5: Jonas Berg | I5: Rosa Ortega | J5: Chloe Nakamura | M5: 46279 | N5: 3 | O5: https://adyen.my.salesforce.com/0016ZF3MwRjiDpu
A6: 00162BGzhEN5XoA | B6: Alder Market | C6: SMB | D6: marketplace | E6: NA | F6: 117000 | G6: 45817 | H6: Jonas Berg | I6: Zoe Jansen | J6: Ravi Greco | N6: 2 | O6: https://adyen.my.salesforce.com/00162BGzhEN5XoA
A7: 0016NkeJdMTfR6E | B7: Arcturus Gear | C7: Mid-Market | D7: ecommerce | E7: NA | F7: 1973000 | G7: 45652 | H7: Daniel Okafor | I7: Maya Yilmaz | J7: Hugo Greco | N7: 4 | O7: https://adyen.my.salesforce.com/0016NkeJdMTfR6E
A8: 0016mSUYH5MAj9V | B8: Ashgrove Cloud | C8: Enterprise | D8: subscription | E8: NA | F8: 3789000 | G8: 43317 | H8: Priya Raman | I8: Freya Lindqvist | J8: Pedro Nakamura | M8: 46272 | N8: 6 | O8: https://adyen.my.salesforce.com/0016mSUYH5MAj9V
A9: 0016axBUXmySHHN | B9: Ashgrove Eats | C9: SMB | D9: food delivery | E9: NA | F9: 96000 | G9: 44643 | H9: Daniel Okafor | I9: Wen Nakamura | J9: Viktor Quinn | N9: 3 | O9: https://adyen.my.salesforce.com/0016axBUXmySHHN
A10: 0016EoWxnCbxbnQ | B10: Ashgrove Hub | C10: SMB | D10: marketplace | E10: EMEA | F10: 115000 | G10: 45594 | H10: Tom Whitaker | I10: Maya Park | J10: Pedro Castillo | N10: 2 | O10: https://adyen.my.salesforce.com/0016EoWxnCbxbnQ
A11: 00164Hj0Tb00oba | B11: Ashgrove Plus | C11: Mid-Market | D11: subscription | E11: EMEA | F11: 934000 | G11: 44780 | H11: Sofia Marquez | I11: Chloe Quinn | J11: Wen Jansen | N11: 3 | O11: https://adyen.my.salesforce.com/00164Hj0Tb00oba
A12: 0016zEAfqnGEkPi | B12: Bazaarly | C12: SMB | D12: marketplace | E12: EMEA | F12: 214000 | G12: 44923 | H12: Sofia Marquez | I12: Isla Moreau | J12: Olivia Kowalski | N12: 1 | O12: https://adyen.my.salesforce.com/0016zEAfqnGEkPi
A13: 0016rEDjrusmgtv | B13: Bellhaven Delivery | C13: SMB | D13: food delivery | E13: EMEA | F13: 106000 | G13: 44261 | H13: Lena Fischer | I13: Tara Silva | J13: Felix Silva | N13: 2 | O13: https://adyen.my.salesforce.com/0016rEDjrusmgtv
A14: 0016osLuEHLKjXu | B14: Bellhaven Eats | C14: SMB | D14: food delivery | E14: APAC | F14: 115000 | G14: 45783 | H14: Jonas Berg | I14: Jakob Zhou | J14: Viktor Quinn | N14: 1 | O14: https://adyen.my.salesforce.com/0016osLuEHLKjXu
A15: 0016STi5EiELJ6z | B15: Bellhaven Kitchen | C15: Enterprise | D15: food delivery | E15: EMEA | F15: 6893000 | G15: 45598 | H15: Tom Whitaker | I15: Wen Brooks | J15: Hana Greco | M15: 46195 | N15: 3 | O15: https://adyen.my.salesforce.com/0016STi5EiELJ6z
A16: 0016HMShP4zhwFP | B16: Bellhaven Market | C16: Mid-Market | D16: marketplace | E16: EMEA | F16: 437000 | G16: 43575 | H16: Priya Raman | I16: Freya Silva | J16: Olivia Andersen | N16: 5 | O16: https://adyen.my.salesforce.com/0016HMShP4zhwFP
A17: 0016607G0dQM2vj | B17: Bluegate Stays | C17: SMB | D17: travel | E17: APAC | F17: 91000 | G17: 43876 | H17: Sofia Marquez | I17: Maya Hansen | J17: Ravi Zhou | N17: 2 | O17: https://adyen.my.salesforce.com/0016607G0dQM2vj
A18: 0016JUe7vhHBrp2 | B18: Bowlrider | C18: Mid-Market | D18: food delivery | E18: APAC | F18: 1181000 | G18: 43339 | H18: Lena Fischer | I18: Olivia Zhou | J18: Isla Rossi | N18: 1 | O18: https://adyen.my.salesforce.com/0016JUe7vhHBrp2
A19: 0016eRzfnqtaXBh | B19: Brewcrate | C19: SMB | D19: subscription | E19: APAC | F19: 166000 | G19: 43474 | H19: Jonas Berg | I19: Isla Kowalski | J19: Isla Park | N19: 1 | O19: https://adyen.my.salesforce.com/0016eRzfnqtaXBh
A20: 0016TVSQHxNWHyk | B20: Brightline Pharmacy | C20: SMB | D20: retail | E20: EMEA | F20: 184000 | G20: 44158 | H20: Lena Fischer | I20: Aiko Rossi | J20: Zoe Ortega | N20: 1 | O20: https://adyen.my.salesforce.com/0016TVSQHxNWHyk
A21: 0016LW8mWVBmoUK | B21: Brookfield Club | C21: Mid-Market | D21: subscription | E21: EMEA | F21: 432000 | G21: 43774 | H21: Jonas Berg | I21: Kara Lindqvist | J21: Leo Varga | N21: 5 | O21: https://adyen.my.salesforce.com/0016LW8mWVBmoUK
A22: 0016MT5AbVDN746 | B22: Brookfield Delivery | C22: SMB | D22: food delivery | E22: EMEA | F22: 143000 | G22: 43869 | H22: Priya Raman | I22: Olivia Varga | J22: Aiko Zhou | N22: 3 | O22: https://adyen.my.salesforce.com/0016MT5AbVDN746
A23: 0016KR15hvaAxfS | B23: Brookfield Exchange | C23: SMB | D23: marketplace | E23: EMEA | F23: 105000 | G23: 43621 | H23: Lena Fischer | I23: Olivia Brooks | J23: David Quinn | N23: 2 | O23: https://adyen.my.salesforce.com/0016KR15hvaAxfS
A24: 0016dKWKsGBp8oB | B24: Brookfield Market | C24: Mid-Market | D24: marketplace | E24: APAC | F24: 464000 | G24: 44180 | H24: Daniel Okafor | I24: Aiko Rossi | J24: Aiko Rossi | N24: 6 | O24: https://adyen.my.salesforce.com/0016dKWKsGBp8oB
A25: 0016S11rot2NdHk | B25: Cascade Optics | C25: SMB | D25: retail | E25: EMEA | F25: 48000 | G25: 43005 | H25: Priya Raman | I25: Jakob Weber | J25: Yusuf Hansen | N25: 3 | O25: https://adyen.my.salesforce.com/0016S11rot2NdHk
A26: 0016SVY0tPvjvw4 | B26: Cinderleaf Bazaar | C26: SMB | D26: marketplace | E26: APAC | F26: 48000 | G26: 44691 | H26: Daniel Okafor | I26: Kara Nakamura | J26: Chloe Laurent | N26: 3 | O26: https://adyen.my.salesforce.com/0016SVY0tPvjvw4
A27: 0016d9VL1tKxep4 | B27: Cinderleaf Bites | C27: Mid-Market | D27: food delivery | E27: APAC | F27: 988000 | G27: 45742 | H27: Lena Fischer | I27: Noah Varga | J27: Hana Castillo | N27: 4 | O27: https://adyen.my.salesforce.com/0016d9VL1tKxep4
... A42: 00165jLDiF5MEpE | B42: Craftloom | C42: Mid-Market | D42: marketplace | E42: NA | F42: 1285000 | G42: 44616 | H42: Daniel Okafor | I42: Ben Brooks | J42: Rosa Lindqvist | N42: 5 | O42: https://adyen.my.salesforce.com/00165jLDiF5MEpE
A43: 00165LXcvhUtb3z | B43: Dishdash Express | C43: Enterprise | D43: food delivery | E43: NA | F43: 12585000 | G43: 43975 | H43: Daniel Okafor | I43: Leo Nakamura | J43: Yusuf Dubois | M43: 46190 | N43: 6 | O43: https://adyen.my.salesforce.com/00165LXcvhUtb3z
A44: 0016zCyHrzdbcgJ | B44: Dovetail Club | C44: Enterprise | D44: subscription | E44: EMEA | F44: 4356000 | G44: 45225 | H44: Lena Fischer | I44: Omar Park | J44: Ravi Petrov | M44: 46198 | N44: 4 | O44: https://adyen.my.salesforce.com/0016zCyHrzdbcgJ
A45: 0016cvnqjEE5PZK | B45: Dovetail Delivery | C45: SMB | D45: food delivery | E45: EMEA | F45: 62000 | G45: 44191 | H45: Priya Raman | I45: Tara Castillo | J45: Leo Ito | N45: 3 | O45: https://adyen.my.salesforce.com/0016cvnqjEE5PZK
A46: 0016oSP17kqgkiy | B46: Dovetail Exchange | C46: Mid-Market | D46: marketplace | E46: NA | F46: 924000 | G46: 44692 | H46: Priya Raman | I46: Omar Kowalski | J46: Hana Hansen | N46: 6 | O46: https://adyen.my.salesforce.com/0016oSP17kqgkiy
A47: 0016C9zUAVgiFvV | B47: Driftwood Bazaar | C47: Mid-Market | D47: marketplace | E47: NA | F47: 1190000 | G47: 43306 | H47: Tom Whitaker | I47: Omar Bakker | J47: Ravi Andersen | N47: 3 | O47: https://adyen.my.salesforce.com/0016C9zUAVgiFvV
A48: 0016pPQMbUWDjE4 | B48: Driftwood Cloud | C48: Mid-Market | D48: subscription | E48: EMEA | F48: 559000 | G48: 44429 | H48: Tom Whitaker | I48: Pedro Varga | J48: Olivia Dubois | N48: 4 | O48: https://adyen.my.salesforce.com/0016pPQMbUWDjE4
A49: 0016A8JFKLQ8QwG | B49: Driftwood Eats | C49: SMB | D49: food delivery | E49: EMEA | F49: 139000 | G49: 43341 | H49: Lena Fischer | I49: Elena Bakker | J49: Hugo Petrov | N49: 3 | O49: https://adyen.my.salesforce.com/0016A8JFKLQ8QwG
A50: 0016MX7TBxHdPRw | B50: Driftwood Hub | C50: SMB | D50: marketplace | E50: EMEA | F50: 47000 | G50: 45503 | H50: Daniel Okafor | I50: Yusuf Bakker | J50: Viktor Eriksen | N50: 2 | O50: https://adyen.my.salesforce.com/0016MX7TBxHdPRw
A51: 0016URbhtJprNjp | B51: Driftwood Market | C51: SMB | D51: marketplace | E51: NA | F51: 96000 | G51: 45523 | H51: Lena Fischer | I51: Mateo Kowalski | J51: Maya Costa | N51: 3 | O51: https://adyen.my.salesforce.com/0016URbhtJprNjp
A52: 0016T8TJSutz6kM | B52: Driftwood Plus | C52: Mid-Market | D52: subscription | E52: EMEA | F52: 1045000 | G52: 43473 | H52: Priya Raman | I52: David Dubois | J52: Isla Ito | N52: 4 | O52: https://adyen.my.salesforce.com/0016T8TJSutz6kM
A53: 0016UFYqxNFP0nA | B53: Elmstead Bites | C53: Mid-Market | D53: food delivery | E53: NA | F53: 471000 | G53: 44240 | H53: Daniel Okafor | I53: Viktor Ito | J53: Olivia Varga | N53: 5 | O53: https://adyen.my.salesforce.com/0016UFYqxNFP0nA
A54: 0016Qt8f64ouF32 | B54: Elmstead Club | C54: SMB | D54: subscription | E54: APAC | F54: 109000 | G54: 44860 | H54: Lena Fischer | I54: Sam Bakker | J54: Jakob Novak | N54: 1 | O54: https://adyen.my.salesforce.com/0016Qt8f64ouF32
...

Sheet SF Contacts
A1: Contact Id | B1: Account Id | C1: Account Name | D1: Name | E1: Title | F1: Role (PriorityOne) | G1: Email | H1: Primary Contact | I1: Last Activity | J1: Left Company On | K1: Record URL
A2: 003fiwgwjZxfxB5 | B2: 0016JihFzD6HKrL | C2: Nordvik Outfitters | D2: Leo Hansen | E2: Payments Lead | F2: Day-to-day lead | G2: leo.hansen@nordvikoutfitters.example | H2: Yes | I2: 46183 | K2: https://adyen.my.salesforce.com/003fiwgwjZxfxB5
A3: 003yJS7yDLDZQeN | B3: 0016JihFzD6HKrL | C3: Nordvik Outfitters | D3: Hana Fontaine | E3: Treasury Manager | F3: Finance | G3: hana.fontaine@nordvikoutfitters.example | I3: 46248 | K3: https://adyen.my.salesforce.com/003yJS7yDLDZQeN
A4: 003Yizs5WitbDXT | B4: 0016JihFzD6HKrL | C4: Nordvik Outfitters | D4: Hugo Eriksen | E4: Engineering Manager, Payments | F4: Technical | G4: hugo.eriksen@nordvikoutfitters.example | I4: 46263 | K4: https://adyen.my.salesforce.com/003Yizs5WitbDXT
A5: 003mcaeRt0KzDes | B5: 0016JihFzD6HKrL | C5: Nordvik Outfitters | D5: Elena Castillo | E5: VP E-commerce | F5: Decision maker | G5: elena.castillo@nordvikoutfitters.example | I5: 46274 | K5: https://adyen.my.salesforce.com/003mcaeRt0KzDes
A6: 003CzuG3D0g9bmW | B6: 0016m6AuxHu7kzT | C6: Lumen & Lark | D6: Rosa Ito | E6: Head of Payments | F6: Day-to-day lead | G6: rosa.ito@lumenlark.example | H6: Yes | I6: 46166 | K6: https://adyen.my.salesforce.com/003CzuG3D0g9bmW
A7: 003K39MNkXsZtNg | B7: 0016m6AuxHu7kzT | C7: Lumen & Lark | D7: Ben Moreau | E7: Treasury Manager | F7: Finance | G7: ben.moreau@lumenlark.example | I7: 46283 | K7: https://adyen.my.salesforce.com/003K39MNkXsZtNg
A8: 003YMhNpVGysdEa | B8: 0016m6AuxHu7kzT | C8: Lumen & Lark | D8: Hugo Quinn | E8: Lead Developer, Checkout | F8: Technical | G8: hugo.quinn@lumenlark.example | I8: 46255 | K8: https://adyen.my.salesforce.com/003YMhNpVGysdEa
A9: 003Q3fpRVRN096q | B9: 00167xSizMi9G6r | C9: Cobalt Crate | D9: Anna Yilmaz | E9: Head of Checkout | F9: Day-to-day lead | G9: anna.yilmaz@cobaltcrate.example | H9: Yes | I9: 46169 | K9: https://adyen.my.salesforce.com/003Q3fpRVRN096q
A10: 0034PmXJzMTeWyc | B10: 00167xSizMi9G6r | C10: Cobalt Crate | D10: Noah Hansen | E10: VP Finance | F10: Finance | G10: noah.hansen@cobaltcrate.example | I10: 46280 | K10: https://adyen.my.salesforce.com/0034PmXJzMTeWyc
A11: 003R8nFxrk0aZSN | B11: 0016pWhBHZ742VR | C11: Fernhill Home | D11: Hana Andersen | E11: Head of Payments | F11: Day-to-day lead | G11: hana.andersen@fernhillhome.example | H11: Yes | I11: 46150 | K11: https://adyen.my.salesforce.com/003R8nFxrk0aZSN
A12: 003nqg26tXpLM3m | B12: 0016pWhBHZ742VR | C12: Fernhill Home | D12: Zoe Bakker | E12: CEO | F12: Exec sponsor | G12: zoe.bakker@fernhillhome.example | I12: 46215 | K12: https://adyen.my.salesforce.com/003nqg26tXpLM3m
A13: 003FDskad05Bztd | B13: 0016pWhBHZ742VR | C13: Fernhill Home | D13: Hana Yilmaz | E13: Chief Digital Officer | F13: Decision maker | G13: hana.yilmaz@fernhillhome.example | I13: 46265 | K13: https://adyen.my.salesforce.com/003FDskad05Bztd
A14: 003Kturbt5Pp2ZD | B14: 0016pWhBHZ742VR | C14: Fernhill Home | D14: Sam Ortega | E14: Treasury Manager | F14: Finance | G14: sam.ortega@fernhillhome.example | I14: 46228 | K14: https://adyen.my.salesforce.com/003Kturbt5Pp2ZD
A15: 003mzBipWBXSF6a | B15: 0016pWhBHZ742VR | C15: Fernhill Home | D15: Hugo Ito | E15: Lead Developer, Checkout | F15: Technical | G15: hugo.ito@fernhillhome.example | I15: 46223 | K15: https://adyen.my.salesforce.com/003mzBipWBXSF6a
A16: 003s4CCjbm03ysC | B16: 0016pWhBHZ742VR | C16: Fernhill Home | D16: Zoe Silva | E16: Fraud & Risk Manager | F16: Risk & fraud | G16: zoe.silva@fernhillhome.example | I16: 46285 | K16: https://adyen.my.salesforce.com/003s4CCjbm03ysC
A17: 003ZjGb0ct2A90o | B17: 0016pWhBHZ742VR | C17: Fernhill Home | D17: Yusuf Petrov | E17: Procurement Manager | F17: Procurement | G17: yusuf.petrov@fernhillhome.example | I17: 46241 | K17: https://adyen.my.salesforce.com/003ZjGb0ct2A90o
A18: 0033vyRedJoRpsg | B18: 0016gmLSj6pdPkz | C18: Pebblewave | D18: Elena Varga | E18: Director of E-commerce | F18: Day-to-day lead | G18: elena.varga@pebblewave.example | H18: Yes | I18: 46253 | K18: https://adyen.my.salesforce.com/0033vyRedJoRpsg
A19: 003v9hQJMrTWEXL | B19: 0016gmLSj6pdPkz | C19: Pebblewave | D19: David Laurent | E19: Finance Director | F19: Finance | G19: david.laurent@pebblewave.example | I19: 46290 | K19: https://adyen.my.salesforce.com/003v9hQJMrTWEXL
A20: 003bbErG5222yDG | B20: 0016gmLSj6pdPkz | C20: Pebblewave | D20: Tara Castillo | E20: Lead Developer, Checkout | F20: Technical | G20: tara.castillo@pebblewave.example | I20: 46246 | K20: https://adyen.my.salesforce.com/003bbErG5222yDG
A21: 003VboJzNtHEtf6 | B21: 0016eHRQEXBomQo | C21: Tidewell Apparel | D21: Ravi Quinn | E21: Head of Checkout | F21: Day-to-day lead | G21: ravi.quinn@tidewellapparel.example | H21: Yes | I21: 46173 | K21: https://adyen.my.salesforce.com/003VboJzNtHEtf6
A22: 003MY2q9V2MAJsu | B22: 0016eHRQEXBomQo | C22: Tidewell Apparel | D22: Maya Tanaka | E22: Treasury Manager | F22: Finance | G22: maya.tanaka@tidewellapparel.example | I22: 46281 | K22: https://adyen.my.salesforce.com/003MY2q9V2MAJsu
A23: 003VTi2r4zCBJSS | B23: 0016eHRQEXBomQo | C23: Tidewell Apparel | D23: David Castillo | E23: Lead Developer, Checkout | F23: Technical | G23: david.castillo@tidewellapparel.example | I23: 46227 | K23: https://adyen.my.salesforce.com/003VTi2r4zCBJSS
A24: 003gebquitebtHZ | B24: 0016eHRQEXBomQo | C24: Tidewell Apparel | D24: Tara Eriksen | E24: Chief Digital Officer | F24: Decision maker | G24: tara.eriksen@tidewellapparel.example | I24: 46262 | K24: https://adyen.my.salesforce.com/003gebquitebtHZ
A25: 003wu0WLEYYw6Kh | B25: 00166XEiRTthPkJ | C25: Quillstone Books | D25: Ravi Brooks | E25: Head of Checkout | F25: Day-to-day lead | G25: ravi.brooks@quillstonebooks.example | H25: Yes | I25: 46268 | K25: https://adyen.my.salesforce.com/003wu0WLEYYw6Kh
A26: 003DYhdPYR7LCF5 | B26: 00166XEiRTthPkJ | C26: Quillstone Books | D26: Olivia Kowalski | E26: Operations Manager | F26: Operations | G26: olivia.kowalski@quillstonebooks.example | K26: https://adyen.my.salesforce.com/003DYhdPYR7LCF5
A27: 0038M9Pjn53JXGJ | B27: 0016tdYdcf6xDus | C27: Marigold Market | D27: David Dubois | E27: Director of E-commerce | F27: Day-to-day lead | G27: david.dubois@marigoldmarket.example | H27: Yes | I27: 46237 | K27: https://adyen.my.salesforce.com/0038M9Pjn53JXGJ
A28: 003ZHQW8W24qAU9 | B28: 0016tdYdcf6xDus | C28: Marigold Market | D28: Kara Lindqvist | E28: Finance Director | F28: Finance | G28: kara.lindqvist@marigoldmarket.example | I28: 46168 | K28: https://adyen.my.salesforce.com/003ZHQW8W24qAU9
A29: 003qq9frZSnL14Z | B29: 0016NkeJdMTfR6E | C29: Arcturus Gear | D29: Hugo Greco | E29: Director of E-commerce | F29: Day-to-day lead | G29: hugo.greco@arcturusgear.example | H29: Yes | I29: 46258 | K29: https://adyen.my.salesforce.com/003qq9frZSnL14Z
A30: 003WDvJSeB12kLq | B30: 0016NkeJdMTfR6E | C30: Arcturus Gear | D30: Pedro Ito | E30: Finance Director | F30: Finance | G30: pedro.ito@arcturusgear.example | I30: 46243 | K30: https://adyen.my.salesforce.com/003WDvJSeB12kLq
A31: 0039GtMni68uL6V | B31: 0016NkeJdMTfR6E | C31: Arcturus Gear | D31: Aiko Kowalski | E31: Engineering Manager, Payments | F31: Technical | G31: aiko.kowalski@arcturusgear.example | I31: 46235 | K31: https://adyen.my.salesforce.com/0039GtMni68uL6V
A32: 003ucrc547DQg8G | B32: 0016NkeJdMTfR6E | C32: Arcturus Gear | D32: Sam Eriksen | E32: VP Payments | F32: Decision maker | G32: sam.eriksen@arcturusgear.example | I32: 46236 | K32: https://adyen.my.salesforce.com/003ucrc547DQg8G
A33: 003iJnqk4Lo2MgY | B33: 00165RLchgP6b8D | C33: Velvetine Beauty | D33: Hana Zhou | E33: Director of E-commerce | F33: Day-to-day lead | G33: hana.zhou@velvetinebeauty.example | H33: Yes | I33: 46262 | K33: https://adyen.my.salesforce.com/003iJnqk4Lo2MgY
A34: 003tbVwdXbnFgWP | B34: 00165RLchgP6b8D | C34: Velvetine Beauty | D34: Jakob Lindqvist | E34: Treasury Manager | F34: Finance | G34: jakob.lindqvist@velvetinebeauty.example | I34: 46153 | K34: https://adyen.my.salesforce.com/003tbVwdXbnFgWP
A35: 00368upCd3acSsJ | B35: 00165RLchgP6b8D | C35: Velvetine Beauty | D35: Viktor Bakker | E35: Lead Developer, Checkout | F35: Technical | G35: viktor.bakker@velvetinebeauty.example | I35: 46025 | K35: https://adyen.my.salesforce.com/00368upCd3acSsJ
A36: 003LGhQgFW4BVyf | B36: 00165RLchgP6b8D | C36: Velvetine Beauty | D36: Jakob Yilmaz | E36: VP E-commerce | F36: Decision maker | G36: jakob.yilmaz@velvetinebeauty.example | K36: https://adyen.my.salesforce.com/003LGhQgFW4BVyf
A37: 003pqzz03ugvz32 | B37: 0016x1mtwhKNUPD | C37: Stallbridge | D37: Noah Weber | E37: Head of Checkout | F37: Day-to-day lead | G37: noah.weber@stallbridge.example | H37: Yes | I37: 46212 | K37: https://adyen.my.salesforce.com/003pqzz03ugvz32
A38: 003zHS1GtApYqDr | B38: 0016x1mtwhKNUPD | C38: Stallbridge | D38: Omar Bakker | E38: Chief Operating Officer | F38: Exec sponsor | G38: omar.bakker@stallbridge.example | I38: 46240 | K38: https://adyen.my.salesforce.com/003zHS1GtApYqDr
A39: 003JJGyjSN6tHLb | B39: 0016x1mtwhKNUPD | C39: Stallbridge | D39: Zoe Usman | E39: VP E-commerce | F39: Decision maker | G39: zoe.usman@stallbridge.example | I39: 46277 | K39: https://adyen.my.salesforce.com/003JJGyjSN6tHLb
A40: 0030mSHN9N9QcDG | B40: 0016x1mtwhKNUPD | C40: Stallbridge | D40: Tara Hansen | E40: Treasury Manager | F40: Finance | G40: tara.hansen@stallbridge.example | I40: 46230 | K40: https://adyen.my.salesforce.com/0030mSHN9N9QcDG
...

Sheet SF Contracts
A1: Contract Number | B1: Account Id | C1: Account Name | D1: Status | E1: End Date | F1: Days to Renewal
A2: 00000136 | B2: 001604FPg2A94Rf | C2: Alder Bazaar | D2: Activated | E2: 46540 | F2: =E2-'Source freshness'!$B$3
A3: 00000101 | B3: 0016kz7PLAp9Nh9 | C3: Alder Bites | D3: Activated | E3: 46943 | F3: =E3-'Source freshness'!$B$3
A4: 00000103 | B4: 0016sQhnhNjZAmX | C4: Alder Box | D4: Activated | E4: 46459 | F4: =E4-'Source freshness'!$B$3
A5: 00000180 | B5: 0016ZF3MwRjiDpu | C5: Alder Exchange | D5: Activated | E5: 46702 | F5: =E5-'Source freshness'!$B$3
A6: 00000177 | B6: 00162BGzhEN5XoA | C6: Alder Market | D6: Activated | E6: 46714 | F6: =E6-'Source freshness'!$B$3
A7: 00000009 | B7: 0016NkeJdMTfR6E | C7: Arcturus Gear | D7: Activated | E7: 46722 | F7: =E7-'Source freshness'!$B$3
A8: 00000159 | B8: 0016mSUYH5MAj9V | C8: Ashgrove Cloud | D8: Activated | E8: 46832 | F8: =E8-'Source freshness'!$B$3
A9: 00000094 | B9: 0016axBUXmySHHN | C9: Ashgrove Eats | D9: Activated | E9: 46653 | F9: =E9-'Source freshness'!$B$3
A10: 00000121 | B10: 0016EoWxnCbxbnQ | C10: Ashgrove Hub | D10: Activated | E10: 46697 | F10: =E10-'Source freshness'!$B$3
A11: 00000068 | B11: 00164Hj0Tb00oba | C11: Ashgrove Plus | D11: Activated | E11: 46580 | F11: =E11-'Source freshness'!$B$3
A12: 00000014 | B12: 0016zEAfqnGEkPi | C12: Bazaarly | D12: Activated | E12: 46509 | F12: =E12-'Source freshness'!$B$3
A13: 00000104 | B13: 0016rEDjrusmgtv | C13: Bellhaven Delivery | D13: Activated | E13: 46424 | F13: =E13-'Source freshness'!$B$3
... A181: 00000077 | B181: 0016L8o53B1vb8z | C181: Zephyrine Plus | D181: Activated | E181: 46657 | F181: =E181-'Source freshness'!$B$3

Sheet SF QBR Events
A1: Event Id | B1: Account Id | C1: Account Name | D1: Type | E1: Activity Date | F1: Days Since
A2: 00U000136QBR | B2: 001604FPg2A94Rf | C2: Alder Bazaar | D2: QBR | E2: 46246 | F2: ='Source freshness'!$B$3-E2
A3: 00U000101QBR | B3: 0016kz7PLAp9Nh9 | C3: Alder Bites | D3: QBR | E3: 46284 | F3: ='Source freshness'!$B$3-E3
A4: 00U000103QBR | B4: 0016sQhnhNjZAmX | C4: Alder Box | D4: QBR | E4: 46285 | F4: ='Source freshness'!$B$3-E4
A5: 00U000180QBR | B5: 0016ZF3MwRjiDpu | C5: Alder Exchange | D5: QBR | E5: 46216 | F5: ='Source freshness'!$B$3-E5
A6: 00U000177QBR | B6: 00162BGzhEN5XoA | C6: Alder Market | D6: QBR | E6: 46262 | F6: ='Source freshness'!$B$3-E6
A7: 00U000009QBR | B7: 0016NkeJdMTfR6E | C7: Arcturus Gear | D7: QBR | E7: 46258 | F7: ='Source freshness'!$B$3-E7
A8: 00U000159QBR | B8: 0016mSUYH5MAj9V | C8: Ashgrove Cloud | D8: QBR | E8: 46253 | F8: ='Source freshness'!$B$3-E8
A9: 00U000094QBR | B9: 0016axBUXmySHHN | C9: Ashgrove Eats | D9: QBR | E9: 46276 | F9: ='Source freshness'!$B$3-E9
A10: 00U000121QBR | B10: 0016EoWxnCbxbnQ | C10: Ashgrove Hub | D10: QBR | E10: 46225 | F10: ='Source freshness'!$B$3-E10
A11: 00U000068QBR | B11: 00164Hj0Tb00oba | C11: Ashgrove Plus | D11: QBR | E11: 46282 | F11: ='Source freshness'!$B$3-E11
A12: 00U000014QBR | B12: 0016zEAfqnGEkPi | C12: Bazaarly | D12: QBR | E12: 46209 | F12: ='Source freshness'!$B$3-E12
A13: 00U000104QBR | B13: 0016rEDjrusmgtv | C13: Bellhaven Delivery | D13: QBR | E13: 46284 | F13: ='Source freshness'!$B$3-E13
... A181: 00U000077QBR | B181: 0016L8o53B1vb8z | C181: Zephyrine Plus | D181: QBR | E181: 46187 | F181: ='Source freshness'!$B$3-E181

Sheet Payments weekly
A1: Merchant Account | B1: Account Name | C1: Week Start | D1: Processing Volume (USD) | E1: Auth Rate | F1: Chargeback Rate | G1: Failed Payouts
A2: ACC-00001 | B2: Nordvik Outfitters | C2: 46118 | D2: 12079775 | E2: 0.8835 | F2: 0.00549 | G2: 0
A3: ACC-00001 | B3: Nordvik Outfitters | C3: 46125 | D3: 12274914 | E3: 0.8822 | F3: 0.00523 | G3: 0
A4: ACC-00001 | B4: Nordvik Outfitters | C4: 46132 | D4: 12073510 | E4: 0.8755 | F4: 0.00433 | G4: 1
A5: ACC-00001 | B5: Nordvik Outfitters | C5: 46139 | D5: 11716837 | E5: 0.8826 | F5: 0.00455 | G5: 0
A6: ACC-00001 | B6: Nordvik Outfitters | C6: 46146 | D6: 12223129 | E6: 0.8822 | F6: 0.00494 | G6: 0
A7: ACC-00001 | B7: Nordvik Outfitters | C7: 46153 | D7: 12148562 | E7: 0.8871 | F7: 0.00527 | G7: 0
A8: ACC-00001 | B8: Nordvik Outfitters | C8: 46160 | D8: 11869441 | E8: 0.8762 | F8: 0.00492 | G8: 1
A9: ACC-00001 | B9: Nordvik Outfitters | C9: 46167 | D9: 11892436 | E9: 0.8803 | F9: 0.00539 | G9: 0
A10: ACC-00001 | B10: Nordvik Outfitters | C10: 46174 | D10: 11869007 | E10: 0.8795 | F10: 0.00546 | G10: 0
A11: ACC-00001 | B11: Nordvik Outfitters | C11: 46181 | D11: 12013901 | E11: 0.8766 | F11: 0.00527 | G11: 0
A12: ACC-00001 | B12: Nordvik Outfitters | C12: 46188 | D12: 12106589 | E12: 0.8808 | F12: 0.00507 | G12: 0
A13: ACC-00001 | B13: Nordvik Outfitters | C13: 46195 | D13: 11897439 | E13: 0.8809 | F13: 0.00434 | G13: 0
... A4681: ACC-00180 | B4681: Alder Exchange | C4681: 46293 | D4681: 54652176 | E4681: 0.9009 | F4681: 0.0035 | G4681: 0

Sheet Payment methods
A1: Merchant Account | B1: Account Name | C1: Vertical | D1: Payment Method | E1: Enabled On
A2: ACC-00001 | B2: Nordvik Outfitters | C2: ecommerce | D2: Google Pay | E2: 43535
A3: ACC-00001 | B3: Nordvik Outfitters | C3: ecommerce | D3: Apple Pay | E3: 43557
A4: ACC-00001 | B4: Nordvik Outfitters | C4: ecommerce | D4: Cards | E4: 43563
A5: ACC-00001 | B5: Nordvik Outfitters | C5: ecommerce | D5: PayPal | E5: 43563
A6: ACC-00001 | B6: Nordvik Outfitters | C6: ecommerce | D6: Pix | E6: 43712
A7: ACC-00001 | B7: Nordvik Outfitters | C7: ecommerce | D7: Klarna | E7: 45878
A8: ACC-00002 | B8: Lumen & Lark | C8: ecommerce | D8: Cards | E8: 43477
A9: ACC-00002 | B9: Lumen & Lark | C9: ecommerce | D9: Google Pay | E9: 43485
A10: ACC-00002 | B10: Lumen & Lark | C10: ecommerce | D10: Apple Pay | E10: 43498
A11: ACC-00002 | B11: Lumen & Lark | C11: ecommerce | D11: PayPal | E11: 43502
A12: ACC-00003 | B12: Cobalt Crate | C12: ecommerce | D12: Apple Pay | E12: 45450
A13: ACC-00003 | B13: Cobalt Crate | C13: ecommerce | D13: Google Pay | E13: 45459
... A818: ACC-00180 | B818: Alder Exchange | C818: marketplace | D818: Apple Pay | E818: 44450

Sheet Support tickets
A1: Ticket Id | B1: Merchant Account | C1: Account Name | D1: Priority | E1: Opened On | F1: Status | G1: Closed On | H1: Ticket URL
A2: SEV1-39929 | B2: ACC-00024 | C2: Orbitra Trips | D2: Sev-1 | E2: 46279 | F2: Open | H2: https://support.internal.adyen.com/tickets/SEV1-39929
A3: SEV1-11151 | B3: ACC-00009 | C3: Arcturus Gear | D3: Sev-1 | E3: 46286 | F3: Open | H3: https://support.internal.adyen.com/tickets/SEV1-11151
A4: SEV1-29133 | B4: ACC-00034 | C4: Readwell | D4: Sev-1 | E4: 46293 | F4: Open | H4: https://support.internal.adyen.com/tickets/SEV1-29133
A5: SEV1-22597 | B5: ACC-00090 | C5: Sablewood Plus | D5: Sev-1 | E5: 46293 | F5: Open | H5: https://support.internal.adyen.com/tickets/SEV1-22597

Sheet Support weekly
A1: Merchant Account | B1: Account Name | C1: Week Start | D1: Open Tickets | E1: Open Sev-1
A2: ACC-00001 | B2: Nordvik Outfitters | C2: 46118 | D2: 2 | E2: 0
A3: ACC-00001 | B3: Nordvik Outfitters | C3: 46125 | D3: 2 | E3: 0
A4: ACC-00001 | B4: Nordvik Outfitters | C4: 46132 | D4: 2 | E4: 0
A5: ACC-00001 | B5: Nordvik Outfitters | C5: 46139 | D5: 3 | E5: 0
A6: ACC-00001 | B6: Nordvik Outfitters | C6: 46146 | D6: 4 | E6: 0
A7: ACC-00001 | B7: Nordvik Outfitters | C7: 46153 | D7: 3 | E7: 0
A8: ACC-00001 | B8: Nordvik Outfitters | C8: 46160 | D8: 3 | E8: 0
A9: ACC-00001 | B9: Nordvik Outfitters | C9: 46167 | D9: 2 | E9: 0
A10: ACC-00001 | B10: Nordvik Outfitters | C10: 46174 | D10: 1 | E10: 0
A11: ACC-00001 | B11: Nordvik Outfitters | C11: 46181 | D11: 1 | E11: 0
A12: ACC-00001 | B12: Nordvik Outfitters | C12: 46188 | D12: 0 | E12: 0
A13: ACC-00001 | B13: Nordvik Outfitters | C13: 46195 | D13: 0 | E13: 0
... A4681: ACC-00180 | B4681: Alder Exchange | C4681: 46293 | D4681: 1 | E4681: 0

Sheet Gong calls
A1: Call Id | B1: Account Name | C1: Call Date | D1: Attendees | E1: Call Brief | F1: Risks (extracted) | G1: Opportunities (extracted) | H1: Sentiment | I1: Call URL
A2: 1744491610717492151 | B2: Kestrel Sports | C2: 46105 | D2: Mateo Quinn (Director of E-commerce), Noah Varga (VP Finance), Rosa Laurent (Engineering Manager, Payments), Leo Varga (Procurement Manager), Daniel Okafor (AM), David Rossi (CSM) | E2: Working session with Mateo Quinn on their checkout roadmap. Finance raised a question about interchange++ reporting, which we resolved on the call. Agreed to reconvene in four weeks. | G2: Local payment methods in new markets | H2: 0.4 | I2: https://app.gong.io/call?id=1744491610717492151
A3: 3004472094896416487 | B3: Brewcrate | C3: 46106 | D3: Isla Park (Operations Manager), Jonas Berg (AM), Isla Kowalski (CSM) | E3: Call with Isla Park to review last quarter's payments performance. Finance raised a question about interchange++ reporting, which we resolved on the call. Next step: Isla Kowalski to send a follow-up summary and book the next check-in. | G3: Network tokens to lift recurring auth rates | H3: 0.4 | I3: https://app.gong.io/call?id=3004472094896416487
A4: 9622744343259252707 | B4: Nibblr | C4: 46109 | D4: Mateo Moreau (Head of Payments), Aiko Zhou (Chief Digital Officer), Ravi Fontaine (Treasury Manager), Omar Usman (Head of Platform), Hana Ito (Fraud & Risk Manager), Tom Whitaker (AM), Kara Ito (CSM) | E4: Call with Mateo Moreau to review last quarter's payments performance. Integration is stable and they are on a recent API version. Action: share a benchmark of peer auth rates before the next call. | G4: Network tokens to lift recurring auth rates | H4: 0.5 | I4: https://app.gong.io/call?id=9622744343259252707
A5: 9233372370965776416 | B5: Fernhill Home | C5: 46114 | D5: Hana Andersen (Head of Payments), Sam Ortega (Treasury Manager), Yusuf Petrov (Procurement Manager), Priya Raman (AM), Leo Zhou (CSM) | E5: Monthly check-in with Hana Andersen and Leo Zhou. Finance raised a question about interchange++ reporting, which we resolved on the call. Action: share a benchmark of peer auth rates before the next call. | H5: 0.5 | I5: https://app.gong.io/call?id=9233372370965776416
A6: 3680852100028282519 | B6: Fitpulse | C6: 46123 | D6: Freya Park (Head of Checkout), Elena Quinn (Head of Platform), Daniel Okafor (AM), Omar Nakamura (CSM) | E6: Call with Freya Park to review last quarter's payments performance. Volumes are tracking in line with plan and the team is happy with settlement times. Action: share a benchmark of peer auth rates before the next call. | G6: Local payment methods in new markets | H6: 0.4 | I6: https://app.gong.io/call?id=3680852100028282519
A7: 9221459419145169166 | B7: Meal Atlas | C7: 46124 | D7: Pedro Hansen (Payments Lead), Grace Hansen (VP E-commerce), Tom Whitaker (AM), Aiko Yilmaz (CSM) | E7: Call with Pedro Hansen to review last quarter's payments performance. Integration is stable and they are on a recent API version. Agreed to reconvene in four weeks. | G7: Network tokens to lift recurring auth rates | H7: 0.4 | I7: https://app.gong.io/call?id=9221459419145169166
A8: 9867782646728901202 | B8: Nibblr | C8: 46130 | D8: Mateo Moreau (Head of Payments), Ravi Fontaine (Treasury Manager), Tom Whitaker (AM), Kara Ito (CSM) | E8: Working session with Mateo Moreau on their checkout roadmap. Finance raised a question about interchange++ reporting, which we resolved on the call. Agreed to reconvene in four weeks. | H8: 0.5 | I8: https://app.gong.io/call?id=9867782646728901202
A9: 3587539601840277931 | B9: Gigforge | C9: 46134 | D9: Felix Ortega (Head of Payments), Priya Raman (AM), Ravi Hansen (CSM) | E9: Monthly check-in with Felix Ortega and Ravi Hansen. They walked through plans for further growth in Europe over the next two quarters. Action: share a benchmark of peer auth rates before the next call. | H9: 0.6 | I9: https://app.gong.io/call?id=3587539601840277931
A10: 6602720157698976958 | B10: Orbitra Trips | C10: 46140 | D10: Yusuf Novak (Payments Lead), Sofia Marquez (AM), Yusuf Lindqvist (CSM) | E10: Call with Yusuf Novak to review last quarter's payments performance. They walked through plans for further growth in Asia-Pacific over the next two quarters. Action: share a benchmark of peer auth rates before the next call. | H10: 0.2 | I10: https://app.gong.io/call?id=6602720157698976958
A11: 6651713937525836607 | B11: Hotbox Delivery | C11: 46145 | D11: Yusuf Bakker (Payments Lead), Isla Rossi (Treasury Manager), Jonas Berg (AM), Hana Bakker (CSM) | E11: Monthly check-in with Yusuf Bakker and Hana Bakker. They walked through plans for further growth in Asia-Pacific over the next two quarters. Action: share a benchmark of peer auth rates before the next call. | H11: 0.3 | I11: https://app.gong.io/call?id=6651713937525836607
A12: 7423681444277047375 | B12: Craftloom | C12: 46146 | D12: Rosa Lindqvist (Head of Checkout), Anna Andersen (Head of Platform), Daniel Okafor (AM), Ben Brooks (CSM) | E12: Working session with Rosa Lindqvist on their checkout roadmap. Finance raised a question about interchange++ reporting, which we resolved on the call. Next step: Ben Brooks to send a follow-up summary and book the next check-in. | H12: 0.6 | I12: https://app.gong.io/call?id=7423681444277047375
A13: 9022778452343334487 | B13: Vendora | C13: 46146 | D13: Nina Varga (Head of Payments), Tom Whitaker (AM), Felix Yilmaz (CSM) | E13: Monthly check-in with Nina Varga and Felix Yilmaz. Finance raised a question about interchange++ reporting, which we resolved on the call. Action: share a benchmark of peer auth rates before the next call. | H13: 0.5 | I13: https://app.gong.io/call?id=9022778452343334487
A14: 2902851005377343962 | B14: Readwell | C14: 46157 | D14: Tara Silva (Director of E-commerce), Jonas Berg (AM), Viktor Rossi (CSM) | E14: Monthly check-in with Tara Silva and Viktor Rossi. They walked through plans for further growth in Asia-Pacific over the next two quarters. Action: share a benchmark of peer auth rates before the next call. | H14: 0.3 | I14: https://app.gong.io/call?id=2902851005377343962
A15: 1379080347008720580 | B15: Tunebox | C15: 46159 | D15: Hugo Eriksen (Head of Payments), Nina Weber (Treasury Manager), Daniel Okafor (AM), Hugo Greco (CSM) | E15: Working session with Hugo Eriksen on their checkout roadmap. Integration is stable and they are on a recent API version. Agreed to reconvene in four weeks. | H15: 0.5 | I15: https://app.gong.io/call?id=1379080347008720580
A16: 1561378415715004623 | B16: Platepost | C16: 46163 | D16: Olivia Rossi (Head of Payments), Rosa Costa (VP Finance), Jonas Berg (AM), Omar Petrov (CSM) | E16: Monthly check-in with Olivia Rossi and Omar Petrov. Finance raised a question about interchange++ reporting, which we resolved on the call. Action: share a benchmark of peer auth rates before the next call. | H16: 0.3 | I16: https://app.gong.io/call?id=1561378415715004623
A17: 5196889517893545983 | B17: Tunebox | C17: 46164 | D17: Hugo Eriksen (Head of Payments), Rosa Varga (Procurement Manager), Daniel Okafor (AM), Hugo Greco (CSM) | E17: Working session with Hugo Eriksen on their checkout roadmap. Finance raised a question about interchange++ reporting, which we resolved on the call. Next step: Hugo Greco to send a follow-up summary and book the next check-in. | H17: 0.5 | I17: https://app.gong.io/call?id=5196889517893545983
A18: 4621643073317565540 | B18: Spoonwise | C18: 46171 | D18: Chloe Hansen (Director of E-commerce), Jonas Berg (AM), Sam Andersen (CSM) | E18: Working session with Chloe Hansen on their checkout roadmap. Finance raised a question about interchange++ reporting, which we resolved on the call. Next step: Sam Andersen to send a follow-up summary and book the next check-in. | G18: Network tokens to lift recurring auth rates | H18: 0.5 | I18: https://app.gong.io/call?id=4621643073317565540
A19: 2058002530658750772 | B19: Grubwagon | C19: 46171 | D19: Omar Andersen (Head of Checkout), Aiko Novak (Fraud & Risk Manager), Tom Whitaker (AM), Hana Bakker (CSM) | E19: Call with Omar Andersen to review last quarter's payments performance. Volumes are tracking in line with plan and the team is happy with settlement times. Action: share a benchmark of peer auth rates before the next call. | H19: 0.4 | I19: https://app.gong.io/call?id=2058002530658750772
A20: 9362534146265948511 | B20: Sunpath Holidays | C20: 46175 | D20: Isla Zhou (Head of Operations), Priya Raman (AM), Aiko Novak (CSM) | E20: Monthly check-in with Isla Zhou and Aiko Novak. Volumes are tracking in line with plan and the team is happy with settlement times. Action: share a benchmark of peer auth rates before the next call. | G20: Network tokens to lift recurring auth rates | H20: 0.4 | I20: https://app.gong.io/call?id=9362534146265948511
A21: 9299828592171819367 | B21: Sunpath Holidays | C21: 46175 | D21: Isla Zhou (Head of Operations), Priya Raman (AM), Aiko Novak (CSM) | E21: Working session with Isla Zhou on their checkout roadmap. They walked through plans for further growth in Asia-Pacific over the next two quarters. Next step: Aiko Novak to send a follow-up summary and book the next check-in. | G21: Local payment methods in new markets | H21: 0.3 | I21: https://app.gong.io/call?id=9299828592171819367
A22: 3742423433037594340 | B22: Forkfly | C22: 46181 | D22: Mateo Zhou (Head of Checkout), Priya Raman (AM), Omar Ito (CSM) | E22: Monthly check-in with Mateo Zhou and Omar Ito. Finance raised a question about interchange++ reporting, which we resolved on the call. Agreed to reconvene in four weeks. | G22: Local payment methods in new markets | H22: 0.5 | I22: https://app.gong.io/call?id=3742423433037594340
A23: 4255939755978916215 | B23: Gigforge | C23: 46183 | D23: Felix Ortega (Head of Payments), Priya Raman (AM), Ravi Hansen (CSM) | E23: Call with Felix Ortega to review last quarter's payments performance. Integration is stable and they are on a recent API version. Agreed to reconvene in four weeks. | G23: Network tokens to lift recurring auth rates | H23: 0.3 | I23: https://app.gong.io/call?id=4255939755978916215
A24: 7184261304339684611 | B24: Loopsy | C24: 46186 | D24: Anna Kowalski (Payments Lead), Chloe Castillo (VP Payments), Lena Fischer (AM), Wen Nakamura (CSM) | E24: Monthly check-in with Anna Kowalski and Wen Nakamura. Volumes are tracking in line with plan and the team is happy with settlement times. Next step: Wen Nakamura to send a follow-up summary and book the next check-in. | H24: 0.4 | I24: https://app.gong.io/call?id=7184261304339684611
A25: 9069628474489547911 | B25: Spoonwise | C25: 46186 | D25: Chloe Hansen (Director of E-commerce), Jonas Berg (AM), Sam Andersen (CSM) | E25: Monthly check-in with Chloe Hansen and Sam Andersen. Integration is stable and they are on a recent API version. Agreed to reconvene in four weeks. | H25: 0.7 | I25: https://app.gong.io/call?id=9069628474489547911
A26: 9112210897943275978 | B26: Peakline Tours | C26: 46191 | D26: Anna Brooks (Head of Checkout), Lena Fischer (AM), Jakob Hansen (CSM) | E26: Working session with Anna Brooks on their checkout roadmap. Integration is stable and they are on a recent API version. Next step: Jakob Hansen to send a follow-up summary and book the next check-in. | G26: Local payment methods in new markets | H26: 0.5 | I26: https://app.gong.io/call?id=9112210897943275978
A27: 3952598906333732562 | B27: Fernhill Home | C27: 46194 | D27: Hana Andersen (Head of Payments), Hana Yilmaz (Chief Digital Officer), Priya Raman (AM), Leo Zhou (CSM) | E27: Working session with Hana Andersen on their checkout roadmap. Integration is stable and they are on a recent API version. Agreed to reconvene in four weeks. | H27: 0.5 | I27: https://app.gong.io/call?id=3952598906333732562
A28: 4140098286166395290 | B28: Loopsy | C28: 46196 | D28: Anna Kowalski (Payments Lead), Lena Fischer (AM), Wen Nakamura (CSM) | E28: Monthly check-in with Anna Kowalski and Wen Nakamura. Integration is stable and they are on a recent API version. Next step: Wen Nakamura to send a follow-up summary and book the next check-in. | H28: 0.4 | I28: https://app.gong.io/call?id=4140098286166395290
A29: 1152996696145887329 | B29: Vendora | C29: 46197 | D29: Nina Varga (Head of Payments), Tom Whitaker (AM), Felix Yilmaz (CSM) | E29: Working session with Nina Varga on their checkout roadmap. Volumes are tracking in line with plan and the team is happy with settlement times. Action: share a benchmark of peer auth rates before the next call. | G29: Local payment methods in new markets | H29: 0.5 | I29: https://app.gong.io/call?id=1152996696145887329
A30: 6982479686479123043 | B30: Halcyon Hotels | C30: 46198 | D30: Isla Brooks (Operations Manager), Freya Weber (Head of Operations), Lena Fischer (AM), Rosa Dubois (CSM) | E30: Working session with Isla Brooks on their checkout roadmap. Finance raised a question about interchange++ reporting, which we resolved on the call. Agreed to reconvene in four weeks. | G30: Network tokens to lift recurring auth rates | H30: 0.7 | I30: https://app.gong.io/call?id=6982479686479123043
A31: 7089761957880883950 | B31: Brewcrate | C31: 46207 | D31: Isla Park (Operations Manager), Jonas Berg (AM), Isla Kowalski (CSM) | E31: Call with Isla Park to review last quarter's payments performance. Volumes are tracking in line with plan and the team is happy with settlement times. Next step: Isla Kowalski to send a follow-up summary and book the next check-in. | G31: Network tokens to lift recurring auth rates | H31: 0.4 | I31: https://app.gong.io/call?id=7089761957880883950
A32: 2348884663563631456 | B32: Hotbox Delivery | C32: 46207 | D32: Yusuf Bakker (Payments Lead), Isla Rossi (Treasury Manager), Jonas Berg (AM), Hana Bakker (CSM) | E32: Working session with Yusuf Bakker on their checkout roadmap. Integration is stable and they are on a recent API version. Action: share a benchmark of peer auth rates before the next call. | H32: 0.5 | I32: https://app.gong.io/call?id=2348884663563631456
A33: 6875699831471747490 | B33: Kestrel Sports | C33: 46209 | D33: Mateo Quinn (Director of E-commerce), Noah Varga (VP Finance), Rosa Laurent (Engineering Manager, Payments), Leo Varga (Procurement Manager), Daniel Okafor (AM), David Rossi (CSM) | E33: Call with Mateo Quinn to review last quarter's payments performance. They walked through plans for further growth in North America over the next two quarters. Next step: David Rossi to send a follow-up summary and book the next check-in. | G33: Network tokens to lift recurring auth rates | H33: 0.3 | I33: https://app.gong.io/call?id=6875699831471747490
A34: 2884276396621620720 | B34: Grubwagon | C34: 46209 | D34: Omar Andersen (Head of Checkout), Aiko Quinn (Engineering Manager, Payments), Aiko Novak (Fraud & Risk Manager), Tom Whitaker (AM), Hana Bakker (CSM) | E34: Monthly check-in with Omar Andersen and Hana Bakker. Volumes are tracking in line with plan and the team is happy with settlement times. Action: share a benchmark of peer auth rates before the next call. | G34: Local payment methods in new markets | H34: 0.4 | I34: https://app.gong.io/call?id=2884276396621620720
A35: 3526501888814739088 | B35: Readwell | C35: 46212 | D35: Tara Silva (Director of E-commerce), Aiko Silva (VP Finance), Aiko Weber (Head of Platform), Jonas Berg (AM), Viktor Rossi (CSM) | E35: Working session with Tara Silva on their checkout roadmap. Volumes are tracking in line with plan and the team is happy with settlement times. Action: share a benchmark of peer auth rates before the next call. | G35: Network tokens to lift recurring auth rates | H35: 0.3 | I35: https://app.gong.io/call?id=3526501888814739088
A36: 6316479136125298050 | B36: Marigold Market | C36: 46218 | D36: David Dubois (Director of E-commerce), Priya Raman (AM), Nina Petrov (CSM) | E36: Call with David Dubois to review last quarter's payments performance. They walked through plans for further growth in Asia-Pacific over the next two quarters. Action: share a benchmark of peer auth rates before the next call. | H36: 0.5 | I36: https://app.gong.io/call?id=6316479136125298050
A37: 4973875268230024377 | B37: Halcyon Hotels | C37: 46218 | D37: Isla Brooks (Operations Manager), Lena Fischer (AM), Rosa Dubois (CSM) | E37: Monthly check-in with Isla Brooks and Rosa Dubois. Finance raised a question about interchange++ reporting, which we resolved on the call. Next step: Rosa Dubois to send a follow-up summary and book the next check-in. | H37: 0.5 | I37: https://app.gong.io/call?id=4973875268230024377
A38: 7829207077766985137 | B38: Platepost | C38: 46221 | D38: Olivia Rossi (Head of Payments), Rosa Costa (VP Finance), Jonas Berg (AM), Omar Petrov (CSM) | E38: Monthly check-in with Olivia Rossi and Omar Petrov. Volumes are tracking in line with plan and the team is happy with settlement times. Action: share a benchmark of peer auth rates before the next call. | H38: 0.4 | I38: https://app.gong.io/call?id=7829207077766985137
A39: 3087629616994378432 | B39: Rentaroo | C39: 46222 | D39: Tara Tanaka (Payments Lead), Omar Park (VP Finance), Sofia Marquez (AM), David Park (CSM) | E39: Monthly check-in with Tara Tanaka and David Park. Volumes are tracking in line with plan and the team is happy with settlement times. Action: share a benchmark of peer auth rates before the next call. | G39: Network tokens to lift recurring auth rates | H39: 0.2 | I39: https://app.gong.io/call?id=3087629616994378432
A40: 2105895420035335872 | B40: Bazaarly | C40: 46229 | D40: Olivia Kowalski (Head of Payments), Sofia Marquez (AM), Isla Moreau (CSM) | E40: Call with Olivia Kowalski to review last quarter's payments performance. Integration is stable and they are on a recent API version. Next step: Isla Moreau to send a follow-up summary and book the next check-in. | G40: Local payment methods in new markets | H40: 0.6 | I40: https://app.gong.io/call?id=2105895420035335872
...

Sheet Slack messages
A1: Channel | B1: Account Name | C1: Posted On | D1: Author | E1: Message | F1: Classified As | G1: Feeds Signal
A2: #shared-platepost | B2: Platepost | C2: 46294 | D2: Olivia Rossi (Platepost) | E2: Hi all, today is my last day at Platepost. Olivia Ito will be your contact for payments from now on. Thanks for everything! | F2: Contact change | G2: contact_departed
A3: #shared-cinderleaf-eats | B3: Cinderleaf Eats | C3: 46296 | D3: Yusuf Novak (Cinderleaf Eats) | E3: Can someone confirm when the September settlement report will be ready? | F3: No signal
A4: #shared-handpicked-hub | B4: Handpicked Hub | C4: 46296 | D4: Omar Laurent (Handpicked Hub) | E4: Is there a sandbox we can use to test the new 3DS flow? | F4: No signal
A5: #shared-emberly-market | B5: Emberly Market | C5: 46296 | D5: Freya Andersen (Emberly Market) | E5: Could you re-send the invoice for August? Finance can't find it. | F5: No signal
A6: #shared-cinderleaf-box | B6: Cinderleaf Box | C6: 46296 | D6: Anna Park (Cinderleaf Box) | E6: Quick question on payout timing for the new EUR account. | F6: No signal
A7: #shared-valemont-club | B7: Valemont Club | C7: 46300 | D7: Elena Costa (Valemont Club) | E7: Thanks for the quick fix on the webhook delays yesterday! | F7: No signal
A8: #shared-ashgrove-cloud | B8: Ashgrove Cloud | C8: 46300 | D8: Pedro Nakamura (Ashgrove Cloud) | E8: Heads-up: we launch our autumn promo on Monday, so expect higher volume. | F8: No signal
A9: #shared-forkfly | B9: Forkfly | C9: 46300 | D9: Mateo Zhou (Forkfly) | E9: Great session today, sharing the slides with the team. | F9: No signal
A10: #shared-copperleaf-delivery | B10: Copperleaf Delivery | C10: 46300 | D10: Tara Greco (Copperleaf Delivery) | E10: We'd like to add two more users to the Customer Area. | F10: No signal

Sheet NPS responses
A1: Response Id | B1: Account Name | C1: Respondent | D1: Score (0-10) | E1: Category | F1: Submitted On
A2: NPS-00151-260422 | B2: Mapleton Delivery | C2: Aiko Lindqvist | D2: 9 | E2: =IF(D2>=9,"Promoter",IF(D2>=7,"Passive","Detractor")) | F2: 46134
A3: NPS-00017-260424 | B3: Loopsy | C3: Yusuf Andersen | D3: 7 | E3: =IF(D3>=9,"Promoter",IF(D3>=7,"Passive","Detractor")) | F3: 46136
A4: NPS-00060-260427 | B4: Hotbox Delivery | C4: Yusuf Bakker | D4: 8 | E4: =IF(D4>=9,"Promoter",IF(D4>=7,"Passive","Detractor")) | F4: 46139
A5: NPS-00069-260429 | B5: Ivorybay Delivery | C5: Ravi Nakamura | D5: 7 | E5: =IF(D5>=9,"Promoter",IF(D5>=7,"Passive","Detractor")) | F5: 46141
A6: NPS-00051-260430 | B6: Snackrun | C6: Chloe Tanaka | D6: 9 | E6: =IF(D6>=9,"Promoter",IF(D6>=7,"Passive","Detractor")) | F6: 46142
A7: NPS-00006-260430 | B7: Tidewell Apparel | C7: Ravi Quinn | D7: 7 | E7: =IF(D7>=9,"Promoter",IF(D7>=7,"Passive","Detractor")) | F7: 46142
A8: NPS-00180-260503 | B8: Alder Exchange | C8: Chloe Nakamura | D8: 7 | E8: =IF(D8>=9,"Promoter",IF(D8>=7,"Passive","Detractor")) | F8: 46145
A9: NPS-00158-260503 | B9: Bellhaven Market | C9: Olivia Andersen | D9: 10 | E9: =IF(D9>=9,"Promoter",IF(D9>=7,"Passive","Detractor")) | F9: 46145
A10: NPS-00055-260503 | B10: Bowlrider | C10: Isla Rossi | D10: 7 | E10: =IF(D10>=9,"Promoter",IF(D10>=7,"Passive","Detractor")) | F10: 46145
A11: NPS-00123-260504 | B11: Copperleaf Delivery | C11: Tara Greco | D11: 8 | E11: =IF(D11>=9,"Promoter",IF(D11>=7,"Passive","Detractor")) | F11: 46146
A12: NPS-00144-260504 | B12: Pinecrest Cloud | C12: Nina Tanaka | D12: 10 | E12: =IF(D12>=9,"Promoter",IF(D12>=7,"Passive","Detractor")) | F12: 46146
A13: NPS-00013-260504 | B13: Rentaroo | C13: Tara Tanaka | D13: 9 | E13: =IF(D13>=9,"Promoter",IF(D13>=7,"Passive","Detractor")) | F13: 46146
... A128: NPS-00142-261001 | B128: Copperleaf Kitchen | C128: Elena Lindqvist | D128: 3 | E128: =IF(D128>=9,"Promoter",IF(D128>=7,"Passive","Detractor")) | F128: 46296

Sheet Sync log
A1: Source | B1: Synced On | C1: Rows Synced
A2: gong | B2: 46118 | C2: 110
A3: gong | B3: 46119 | C3: 306
A4: gong | B4: 46120 | C4: 158
A5: gong | B5: 46121 | C5: 196
A6: gong | B6: 46122 | C6: 323
A7: gong | B7: 46123 | C7: 147
A8: gong | B8: 46124 | C8: 102
A9: gong | B9: 46125 | C9: 230
A10: gong | B10: 46126 | C10: 112
A11: gong | B11: 46127 | C11: 58
A12: gong | B12: 46128 | C12: 160
A13: gong | B13: 46129 | C13: 397
... A930: survey | B930: 46297 | C930: 21

Sheet Source freshness
A1: Source freshness
A3: Week being scored (Monday) | B3: 46300 | C3: ← input: change it to check freshness as of another week
A4: A source is stale when its newest sync is more than 7 days before the week being scored.
A6: Source | B6: Newest Sync | C6: Days Behind | D6: Stale? | E6: Feeds
A7: payments_db | B7: =_xlfn.MAXIFS('Sync log'!$B:$B,'Sync log'!$A:$A,A7) | C7: =$B$3-B7 | D7: =IF(C7>7,"Yes","No") | E7: volume, auth rate, chargebacks, payouts, payment methods
A8: salesforce | B8: =_xlfn.MAXIFS('Sync log'!$B:$B,'Sync log'!$A:$A,A8) | C8: =$B$3-B8 | D8: =IF(C8>7,"Yes","No") | E8: renewals, QBRs, contacts, exec sponsor, threading
A9: gong | B9: =_xlfn.MAXIFS('Sync log'!$B:$B,'Sync log'!$A:$A,A9) | C9: =$B$3-B9 | D9: =IF(C9>7,"Yes","No") | E9: call notes, cross-sell, sentiment, no-contact
A10: support | B10: =_xlfn.MAXIFS('Sync log'!$B:$B,'Sync log'!$A:$A,A10) | C10: =$B$3-B10 | D10: =IF(C10>7,"Yes","No") | E10: sev-1 tickets
A11: slack | B11: =_xlfn.MAXIFS('Sync log'!$B:$B,'Sync log'!$A:$A,A11) | C11: =$B$3-B11 | D11: =IF(C11>7,"Yes","No") | E11: contact changes
A12: survey | B12: =_xlfn.MAXIFS('Sync log'!$B:$B,'Sync log'!$A:$A,A12) | C12: =$B$3-B12 | D12: =IF(C12>7,"Yes","No") | E12: NPS

Sheet Signals (output)
A1: Account Name | B1: Signal | C1: Severity | D1: Detected On | E1: Resolved On | F1: Resolution | G1: Source System | H1: Summary | I1: Source Link
A2: Pemberton Shoes | B2: no_contact_90d | C2: low | D2: 46157 | G2: gong | H2: No recorded call or QBR since 13 Feb 2026. | I2: https://app.gong.io/account?crm-id=0016Vpy3n9UeHfv
A3: Learnhive | B3: no_contact_90d | C3: low | D3: 46165 | G3: gong | H3: No recorded call or QBR since 21 Feb 2026. | I3: https://app.gong.io/account?crm-id=00161CYkdtZEisX
A4: Urban Kettle | B4: no_contact_90d | C4: low | D4: 46176 | G4: gong | H4: No recorded call or QBR since 04 Mar 2026. | I4: https://app.gong.io/account?crm-id=0016zjpUG4NUQZM
A5: Petpal Club | B5: no_contact_90d | C5: low | D5: 46187 | G5: gong | H5: No recorded call or QBR since 15 Mar 2026. | I5: https://app.gong.io/account?crm-id=0016dMxjsTq29k0
A6: Snackrun | B6: no_contact_90d | C6: low | D6: 46196 | G6: gong | H6: No recorded call or QBR since 24 Mar 2026. | I6: https://app.gong.io/account?crm-id=0016C7dyWpSBFQu
A7: Gardenly | B7: no_contact_90d | C7: low | D7: 46205 | E7: 46279 | F7: cleared | G7: gong | H7: No recorded call or QBR since 02 Apr 2026. | I7: https://app.gong.io/account?crm-id=0016nu9abwNEov4
A8: Zephyrine Market | B8: no_contact_90d | C8: low | D8: 46231 | G8: gong | H8: No recorded call or QBR since 28 Apr 2026. | I8: https://app.gong.io/account?crm-id=0016X0zw2m5yRn8
A9: Riverbend Hub | B9: no_contact_90d | C9: low | D9: 46232 | G9: gong | H9: No recorded call or QBR since 29 Apr 2026. | I9: https://app.gong.io/account?crm-id=0016w8ej6Zh6qRD
A10: Sablewood Bazaar | B10: no_contact_90d | C10: low | D10: 46240 | G10: gong | H10: No recorded call or QBR since 07 May 2026. | I10: https://app.gong.io/account?crm-id=0016DQXyH5LPVSB
A11: Jetwise | B11: no_contact_90d | C11: low | D11: 46241 | G11: gong | H11: No recorded call or QBR since 08 May 2026. | I11: https://app.gong.io/account?crm-id=0016Wz8eq3x8id4
A12: Willowmere Kitchen | B12: no_contact_90d | C12: low | D12: 46242 | G12: gong | H12: No recorded call or QBR since 09 May 2026. | I12: https://app.gong.io/account?crm-id=0016bDuMhdpjXsY
A13: Cinderleaf Eats | B13: no_contact_90d | C13: low | D13: 46242 | G13: gong | H13: No recorded call or QBR since 09 May 2026. | I13: https://app.gong.io/account?crm-id=00165a3W7X9qvH4
A14: Nomadique | B14: no_contact_90d | C14: low | D14: 46246 | G14: gong | H14: No recorded call or QBR since 13 May 2026. | I14: https://app.gong.io/account?crm-id=001681yLtFUitrq
A15: Pemberton Shoes | B15: qbr_overdue | C15: low | D15: 46247 | G15: salesforce | H15: Last QBR was on 13 Feb 2026, more than 180 days ago. | I15: https://adyen.my.salesforce.com/0016Vpy3n9UeHfv
A16: Cinderleaf Bites | B16: no_contact_90d | C16: low | D16: 46248 | G16: gong | H16: No recorded call or QBR since 15 May 2026. | I16: https://app.gong.io/account?crm-id=0016d9VL1tKxep4
A17: Larkspur Club | B17: no_contact_90d | C17: low | D17: 46249 | G17: gong | H17: No recorded call or QBR since 16 May 2026. | I17: https://app.gong.io/account?crm-id=0016w79V2tM8uh1
A18: Swapnest | B18: volume_drop | C18: medium | D18: 46251 | E18: 46258 | F18: superseded | G18: payments_db | H18: Weekly processing volume fell 25% to $298k, from a $396k baseline. | I18: https://looker.internal.adyen.com/dashboards/merchant-health?account=ACC-00019&metric=volume&week=2026-08-10
A19: Oakmere Department Stores | B19: volume_drop | C19: medium | D19: 46251 | E19: 46258 | F19: superseded | G19: payments_db | H19: Weekly processing volume fell 22% to $865k, from a $1.1M baseline. | I19: https://looker.internal.adyen.com/dashboards/merchant-health?account=ACC-00042&metric=volume&week=2026-08-10
A20: Linden Toys | B20: volume_drop | C20: medium | D20: 46251 | E20: 46265 | F20: cleared | G20: payments_db | H20: Weekly processing volume fell 25% to $2.3M, from a $3.0M baseline. | I20: https://looker.internal.adyen.com/dashboards/merchant-health?account=ACC-00048&metric=volume&week=2026-08-10
A21: Forkfly | B21: volume_drop | C21: medium | D21: 46251 | E21: 46265 | F21: cleared | G21: payments_db | H21: Weekly processing volume fell 26% to $1.5M, from a $2.0M baseline. | I21: https://looker.internal.adyen.com/dashboards/merchant-health?account=ACC-00052&metric=volume&week=2026-08-10
A22: Tunebox | B22: renewal_approaching | C22: medium | D22: 46252 | E22: 46282 | F22: superseded | G22: salesforce | H22: Contract renews on 17 Oct 2026, inside the 60-day window. | I22: https://adyen.my.salesforce.com/0016gtHnPfvS0ZL
A23: Willowmere Plus | B23: no_contact_90d | C23: low | D23: 46252 | G23: gong | H23: No recorded call or QBR since 19 May 2026. | I23: https://app.gong.io/account?crm-id=0016wEnMxMgo5Bn
A24: Wayfarer Rail | B24: exec_sponsor_gap | C24: low | D24: 46253 | G24: salesforce | H24: No executive-level contact since 19 Feb 2026. | I24: https://adyen.my.salesforce.com/00167SMoSCGpdYx
A25: Zephyrine Bites | B25: no_contact_90d | C25: low | D25: 46254 | G25: gong | H25: No recorded call or QBR since 21 May 2026. | I25: https://app.gong.io/account?crm-id=0016mgkZWiJR28z
A26: Learnhive | B26: qbr_overdue | C26: low | D26: 46255 | G26: salesforce | H26: Last QBR was on 21 Feb 2026, more than 180 days ago. | I26: https://adyen.my.salesforce.com/00161CYkdtZEisX
A27: Lumen & Lark | B27: no_contact_90d | C27: low | D27: 46257 | G27: gong | H27: No recorded call or QBR since 24 May 2026. | I27: https://app.gong.io/account?crm-id=0016m6AuxHu7kzT
A28: Quillstone Books | B28: auth_rate_drop | C28: low | D28: 46258 | E28: 46265 | F28: superseded | G28: payments_db | H28: Authorisation rate dropped 4.4 points to 88.8% (was 93.2%). | I28: https://looker.internal.adyen.com/dashboards/merchant-health?account=ACC-00007&metric=auth_rate&week=2026-08-17
A29: Swapnest | B29: volume_drop | C29: high | D29: 46258 | E29: 46265 | F29: cleared | G29: payments_db | H29: Weekly processing volume fell 32% to $268k, from a $396k baseline. | I29: https://looker.internal.adyen.com/dashboards/merchant-health?account=ACC-00019&metric=volume&week=2026-08-17
